main() is called
fun() is called..!
exception was handled.!
